Workbook

Sheet Resumen
A1: Clientes con deuda pendiente - agrupado por estado de cliente y de contrato
A2: Fuente: base de produccion (vxxzesbmilfolwjhfxgr), tenant Telenet, consulta del 2026-08-11. Solo cuotas pendiente/parcial con saldo mayor a 0.
A3: Una fila por CONTRATO: un cliente con dos contratos aparece dos veces.
A5: Estado cliente | B5: Estado contrato | C5: Contratos | D5: Cuotas pend. | E5: Deuda (C$) | F5: Que significa / accion sugerida
A6: DESACTIVADO | B6: activo | C6: =COUNTIFS(Detalle!$A$5:$A$51,$A6,Detalle!$F$5:$F$51,$B6) -> 0 | D6: =SUMIFS(Detalle!$J$5:$J$51,Detalle!$A$5:$A$51,$A6,Detalle!$F$5:$F$51,$B6) -> 0 | E6: =SUMIFS(Detalle!$L$5:$L$51,Detalle!$A$5:$A$51,$A6,Detalle!$F$5:$F$51,$B6) -> 0 | F6: INVALIDO. Desactivado deberia ser "saldado", pero debe. Ademas el contrato sigue facturando cada mes. Invisible en las 3 pantallas de cobro.
A7: DESACTIVADO | B7: suspendido | C7: =COUNTIFS(Detalle!$A$5:$A$51,$A7,Detalle!$F$5:$F$51,$B7) -> 5 | D7: =SUMIFS(Detalle!$J$5:$J$51,Detalle!$A$5:$A$51,$A7,Detalle!$F$5:$F$51,$B7) -> 24 | E7: =SUMIFS(Detalle!$L$5:$L$51,Detalle!$A$5:$A$51,$A7,Detalle!$F$5:$F$51,$B7) -> 18651.15 | F7: INVALIDO. El corte por mora se hizo bien (contrato suspendido) pero ADEMAS se desactivo al cliente, y eso le esconde la deuda al cobrador.
A8: DESACTIVADO | B8: cancelado | C8: =COUNTIFS(Detalle!$A$5:$A$51,$A8,Detalle!$F$5:$F$51,$B8) -> 2 | D8: =SUMIFS(Detalle!$J$5:$J$51,Detalle!$A$5:$A$51,$A8,Detalle!$F$5:$F$51,$B8) -> 15 | E8: =SUMIFS(Detalle!$L$5:$L$51,Detalle!$A$5:$A$51,$A8,Detalle!$F$5:$F$51,$B8) -> 11816.88 | F8: INVALIDO. Baja con deuda pendiente sin saldar.
A9: ACTIVO | B9: completado | C9: =COUNTIFS(Detalle!$A$5:$A$51,$A9,Detalle!$F$5:$F$51,$B9) -> 0 | D9: =SUMIFS(Detalle!$J$5:$J$51,Detalle!$A$5:$A$51,$A9,Detalle!$F$5:$F$51,$B9) -> 0 | E9: =SUMIFS(Detalle!$L$5:$L$51,Detalle!$A$5:$A$51,$A9,Detalle!$F$5:$F$51,$B9) -> 0 | F9: El estado "completado" se elimina (pasa a cancelado). Hoy no cae en NINGUN filtro de cobro: deuda invisible.
A10: ACTIVO | B10: cancelado | C10: =COUNTIFS(Detalle!$A$5:$A$51,$A10,Detalle!$F$5:$F$51,$B10) -> 39 | D10: =SUMIFS(Detalle!$J$5:$J$51,Detalle!$A$5:$A$51,$A10,Detalle!$F$5:$F$51,$B10) -> 156 | E10: =SUMIFS(Detalle!$L$5:$L$51,Detalle!$A$5:$A$51,$A10,Detalle!$F$5:$F$51,$B10) -> 131445.92 | F10: OK. Ya se ve hoy en "Ver fuera de ruta". No requiere accion.
A11: ACTIVO | B11: suspendido | C11: =COUNTIFS(Detalle!$A$5:$A$51,$A11,Detalle!$F$5:$F$51,$B11) -> 1 | D11: =SUMIFS(Detalle!$J$5:$J$51,Detalle!$A$5:$A$51,$A11,Detalle!$F$5:$F$51,$B11) -> 6 | E11: =SUMIFS(Detalle!$L$5:$L$51,Detalle!$A$5:$A$51,$A11,Detalle!$F$5:$F$51,$B11) -> 7392.87 | F11: OK. Servicio suspendido con deuda previa: es el estado correcto.
A12: TOTAL a decidir | C12: =SUM(C6:C11) -> 47 | D12: =SUM(D6:D11) -> 201 | E12: =SUM(E6:E11) -> 169306.82
A14: Operacion normal (NO incluida en la hoja Detalle)
A15: ACTIVO | B15: activo | C15: 1011 | D15: 4505 | E15: 4495505 | F15: Cartera normal: cliente activo con contrato activo, se cobra como siempre. Valores fijos tomados de la consulta (no salen de la hoja Detalle).

Sheet Detalle
A1: Detalle a decidir - una fila por contrato
A2: COMPLETAR solo la columna "Decision" (amarilla), que tiene lista desplegable. El resto es informacion de la base, no editar.
A3: Fuente: base de produccion (vxxzesbmilfolwjhfxgr), tenant Telenet, consulta del 2026-08-11. Solo cuotas pendiente/parcial con saldo mayor a 0.
A4: Estado cliente | B4: Cod. cliente | C4: Cliente | D4: Comunidad | E4: Cod. contrato | F4: Estado contrato | G4: Plan | H4: Ultimo pago | I4: Meses sin pagar | J4: Cuotas pend. | K4: Vence mas vieja | L4: Deuda (C$) | M4: Decision
A5: ACTIVO | B5: SP0023 | C5: Brandon Francisco Sambrana Guerrero | D5: Santa Pancha | E5: 488 | F5: cancelado | G5: Combo 20M+Catv | J5: 10 | K5: 2026-01-26 | L5: 12820 | M5: EL CONTRATO CANCELADO ESTABA MAL LA FECHA Y CONTRATO, EL QUE ESTA ACTUAL ES EL CORRESPONDIENTE
A6: ACTIVO | B6: MV0049 | C6: Joel Missael Gonzáles Romero | D6: MINVHA | E6: 119 | F6: cancelado | G6: Combo 20M+Catv | J6: 9 | K6: 2026-02-02 | L6: 11538 | M6: CONTRATO CANCELADO POR QUE TENIA MALA EL PAQUETE DEL SERVICIO
A7: ACTIVO | B7: SP0027 | C7: María Soledad Vargas Castro | D7: Santa Pancha | E7: 487 | F7: cancelado | G7: Combo 20M+Catv | J7: 9 | K7: 2026-02-25 | L7: 11538 | M7: CONTRATO CANCELADO POR FECHA MALA
A8: ACTIVO | B8: PM0023 | C8: Emerson Adiel Ramírez Contrera | D8: La Palma | E8: 0432 | F8: cancelado | G8: Combo 20M+Catv | J8: 9 | K8: 2026-02-25 | L8: 11538 | M8: CONTRATO CANCELADO POR PLAN EQUIVOCADO
A9: ACTIVO | B9: SP0014 | C9: Heydi Gabriela Martínez Grio | D9: Santa Pancha | E9: 280 | F9: cancelado | G9: Combo 20M+Catv | J9: 9 | K9: 2026-02-16 | L9: 11538 | M9: CANCELADO POR ERROR DE CONTRATO
A10: ACTIVO | B10: VQ0039 | C10: Miryam Del Carmen Romero | D10: Villa Quince | E10: 272 | F10: cancelado | G10: Promo 1 Catv Gratis | J10: 12 | K10: 2026-01-03 | L10: 10992 | M10: CONTRATO CANCELADO POR PLAN EQUIVOCADO
A11: ACTIVO | B11: SP0024 | C11: María Luisa Reyes Ruíz | D11: Nuevo Asentamiento | E11: 00255 | F11: cancelado | G11: Catv | J11: 12 | K11: 2026-02-12 | L11: 6156 | M11: CONTRATO CANCELADO POR MALA FECHA
A12: ACTIVO | B12: QH0017 | C12: Madelyn Roxana Alduvin Castillo | D12: Quebrada Honda | E12: 0656 | F12: cancelado | G12: Internet 20MB | J12: 7 | K12: 2026-01-19 | L12: 6098.79 | M12: CONTRATO CANCELADO POR MALA FECHA
A13: ACTIVO | B13: LS0006 | C13: María Gertrudis Betancour Rojas | D13: Las Sirenas | E13: 265 | F13: cancelado | G13: Internet 20MB | J13: 7 | K13: 2026-02-09 | L13: 5555.1 | M13: CONTRATO CANCELADO POR MALA FECHA
A14: ACTIVO | B14: SP0106 | C14: Fanny Massiell Medina Toruño 72/100 | D14: Santa Pancha | E14: 0459 | F14: cancelado | G14: Pasate con Nosotros | J14: 10 | K14: 2025-10-11 | L14: 5130 | M14: CONTRATO CANCELADO POR MALA FECHA
A15: ACTIVO | B15: VQ0038 | C15: Marina Lisseth Benavides Mendoza | D15: Villa Quince | E15: 0354 | F15: cancelado | G15: Promo 1 Catv Gratis | H15: 2026-05-08 | I15: 3 | J15: 5 | K15: 2026-04-29 | L15: 3989.03 | M15: cliente cortado
A16: ACTIVO | B16: VQ0031 | C16: Augusto César García Talavera | D16: Villa Quince | E16: 0193 | F16: cancelado | G16: Promo 1 Catv Gratis | H16: 2026-03-09 | I16: 5 | J16: 5 | K16: 2026-05-02 | L16: 3870.84 | M16: cliente cortado
A17: ACTIVO | B17: SP0024 | C17: María Luisa Reyes Ruíz | D17: Nuevo Asentamiento | E17: 0523 | F17: cancelado | G17: Catv | J17: 7 | K17: 2026-04-13 | L17: 3591 | M17: CONTRATO CANCELADO POR ERROR DE FECHA
A18: ACTIVO | B18: MV0148 | C18: Blanca Adriana Pineda Catin | D18: MINVHA | E18: 817 | F18: cancelado | G18: Combo 20M+Catv | H18: 2026-07-23 | I18: 0 | J18: 3 | K18: 2026-06-15 | L18: 3473.81 | M18: CONTRATO CANCELADO POR MALO EL PAQUETE
A19: ACTIVO | B19: VZ0078 | C19: Juan Marcio Ramírez García | D19: Valle los Zapatas | E19: 642 | F19: cancelado | G19: Catv | J19: 6 | K19: 2026-02-14 | L19: 2970.99 | M19: CONTRATO CANCELADO POR MALO EL PAQUETE
A20: ACTIVO | B20: QH0063 | C20: Kiara Gisella Valdivia López | D20: Quebrada Honda | E20: 228 | F20: cancelado | G20: Combo 20M+Catv | H20: 2026-07-28 | I20: 0 | J20: 2 | K20: 2026-07-23 | L20: 1860.97 | M20: CONTRATO CANCELADO POR MALO EL PAQUETE
A21: ACTIVO | B21: VZ0120 | C21: Gioconda Carolina Carvajal Pastrán | D21: Valle los Zapatas | E21: 0434 | F21: cancelado | G21: Combo 20M+Catv | H21: 2026-07-13 | I21: 1 | J21: 2 | K21: 2026-07-27 | L21: 1860.97 | M21: CONTRATO CANCELADO POR MALO EL PAQUETE
A22: ACTIVO | B22: SG0008 | C22: Alexander José Medina Sánchez | D22: San Gil | E22: 00002 | F22: cancelado | G22: Combo 40M+Catv | H22: 2026-07-07 | I22: 1 | J22: 2 | K22: 2026-08-03 | L22: 1860.65 | M22: CONTRATO CANCELADO POR MALO EL PAQUETE
A23: ACTIVO | B23: GG0003 | C23: Ubelda de los Ángeles Cárdenas Ramírez | D23: Mina el Limón | E23: 324 | F23: cancelado | G23: Combo 20M+Catv | H23: 2026-07-30 | I23: 0 | J23: 2 | K23: 2026-08-05 | L23: 1488.77 | M23: CONTRATO CANCELADO POR MALO EL PAQUETE
A24: ACTIVO | B24: VZ0087 | C24: Jorge Emilio Niño González | D24: Valle los Zapatas | E24: 766 | F24: cancelado | G24: Combo 20M+Catv | H24: 2026-06-15 | I24: 1 | J24: 1 | K24: 2026-08-13 | L24: 1157.94 | M24: CONTRATO CANCELADO POR MALO EL PAQUETE
A25: ACTIVO | B25: AS0027 | C25: Félix Pedro Vílchez Martínez | D25: Mina el Limón | E25: 0590 | F25: cancelado | G25: Combo 20M+Catv | H25: 2026-07-26 | I25: 0 | J25: 1 | K25: 2026-08-15 | L25: 1075.23 | M25: CONTRATO CANCELADO POR MALO EL PAQUETE
A26: ACTIVO | B26: VZ0006 | C26: Delia Marina Juárez González | D26: Valle los Zapatas | E26: 702 | F26: cancelado | G26: Internet 40MB | H26: 2026-06-13 | I26: 2 | J26: 1 | K26: 2026-07-13 | L26: 1057.31 | M26: CONTRATO CANCELADO POR MALO EL PAQUETE
A27: ACTIVO | B27: SG0042 | C27: Jorge Enrique Bulle Goyri Barraza | D27: San Gil | E27: 0612 | F27: cancelado | G27: Internet 20MB | H27: 2026-07-02 | I27: 1 | J27: 2 | K27: 2026-08-03 | L27: 1034.19 | M27: CONTRATO CANCELADO POR MALO EL PAQUETE
A28: ACTIVO | B28: EM0008 | C28: Karla Patricia Silva Rodriguez | D28: San Isidro | E28: 809 | F28: cancelado | G28: Catv | H28: 2026-06-18 | I28: 1 | J28: 2 | K28: 2026-07-11 | L28: 943.26 | M28: CONTRATO CANCELADO POR MALO EL PAQUETE
A29: ACTIVO | B29: MV0058 | C29: José Luis Ortíz Castillo | D29: MINVHA | E29: 589 | F29: cancelado | G29: Catv | H29: 2026-07-02 | I29: 1 | J29: 2 | K29: 2026-07-11 | L29: 860.52 | M29: CONTRATO CANCELADO POR MALO EL PAQUETE
A30: ACTIVO | B30: FS0008 | C30: Emiliano Rosalio Aleman Cardoza | D30: Mina el Limón | E30: 87 | F30: cancelado | G30: Promo 2 Catv | H30: 2026-06-24 | I30: 1 | J30: 3 | K30: 2026-07-02 | L30: 851.61 | M30: CONTRATO CANCELADO POR MALO EL PAQUETE
A31: ACTIVO | B31: NA0053 | C31: Eloida Dalila Hernández Sánchez | D31: Nuevo Asentamiento | E31: 0603 | F31: cancelado | G31: Catv | H31: 2026-07-22 | I31: 0 | J31: 2 | K31: 2026-07-22 | L31: 761.23 | M31: CONTRATO CANCELADO POR MALO EL PAQUETE
... A38: ACTIVO | B38: PÑ0064 | C38: Julia Raquel García Hernández | D38: El Piñuelar | E38: 00377 | F38: cancelado | G38: Internet 20MB | H38: 2026-08-04 | I38: 0 | J38: 1 | K38: 2026-08-22 | L38: 443.23 | M38: CONTRATO CANCELADO POR MALO EL PAQUETE
A39: ACTIVO | B39: QH0084 | C39: María Fernanda Chávez Hernández | D39: Quebrada Honda | E39: 0668 | F39: cancelado | G39: Catv | J39: 1 | K39: 2026-08-11 | L39: 430.26 | M39: CONTRATO CANCELADO POR MALO EL PAQUETE
A40: ACTIVO | B40: LQ0072 | C40: Ruth Esther Valdizón Flores | D40: Las Quemadas | E40: 0686 | F40: cancelado | G40: Catv | J40: 1 | K40: 2026-08-14 | L40: 380.61 | M40: CONTRATO CANCELADO POR MALO EL PAQUETE Y EL OTRO SUSPENDIDO
A41: ACTIVO | B41: VQ0003 | C41: Taniuska Liseloth Méndez Cruz | D41: Villa Quince | E41: 0103 | F41: cancelado | G41: Promo 1 Catv Gratis | H41: 2026-08-07 | I41: 0 | J41: 1 | K41: 2026-08-29 | L41: 354.58 | M41: CLIENTE CORTADO
A42: ACTIVO | B42: SP0099 | C42: Mirian Antonia Moreno Casco | D42: Santa Pancha | E42: 0092 | F42: cancelado | G42: Combo 20M+Catv | J42: 1 | K42: 2026-08-05 | L42: 248.13 | M42: CANCELADO POR MALA FECHA ESCRITA
A43: ACTIVO | B43: QH0066 | C43: Marcela Elizabeth Videa Castillo | D43: Quebrada Honda | E43: 00561 | F43: cancelado | G43: Internet 40MB | H43: 2026-08-07 | I43: 0 | J43: 1 | K43: 2026-09-07 | L43: 124.06 | M43: CLIENTE CAMBIO A COMBO
A44: ACTIVO | B44: QH0066 | C44: Marcela Elizabeth Videa Castillo | D44: Quebrada Honda | E44: 561 | F44: suspendido | G44: Combo 20M+Catv | J44: 6 | K44: 2026-02-07 | L44: 7392.87 | M44: CONTRATO CANCELADO POR MALO EL PAQUETE
A45: DESACTIVADO | B45: MV0167 | C45: Juan José Castro López | D45: MINVHA | E45: 0488 | F45: cancelado | G45: Combo 20M+Catv | J45: 6 | K45: 2026-02-27 | L45: 7199.88 | M45: CLIENTE CORTADO
A46: DESACTIVADO | B46: QH0073 | C46: Yoely Mercedes García Reyes | D46: Quebrada Honda | E46: 0372 | F46: cancelado | G46: Catv | J46: 9 | K46: 2026-02-20 | L46: 4617 | M46: CLIENTE CORTADO
...
